[2021-01-23 22:51:59,458: WARNING/MainProcess] /media/rithvij/Storage/Images/pallete/pallete-theme/src/venv/lib/python3.9/site-packages/celery/app/utils.py:204: CDeprecationWarning: 
    The 'CELERY_ACCEPT_CONTENT' setting is deprecated and scheduled for removal in
    version 6.0.0. Use the accept_content instead

  deprecated.warn(description=f'The {setting!r} setting',

[2021-01-23 22:51:59,459: WARNING/MainProcess] /media/rithvij/Storage/Images/pallete/pallete-theme/src/venv/lib/python3.9/site-packages/celery/app/utils.py:204: CDeprecationWarning: 
    The 'CELERY_RESULT_BACKEND' setting is deprecated and scheduled for removal in
    version 6.0.0. Use the result_backend instead

  deprecated.warn(description=f'The {setting!r} setting',

[2021-01-23 22:51:59,459: WARNING/MainProcess] Please run `celery upgrade settings path/to/settings.py` to avoid these warnings and to allow a smoother upgrade to Celery 6.0.
[2021-01-23 22:52:00,143: INFO/MainProcess] Connected to redis://localhost:6379/0
[2021-01-23 22:52:00,157: INFO/MainProcess] mingle: searching for neighbors
[2021-01-23 22:52:01,182: INFO/MainProcess] mingle: all alone
[2021-01-23 22:52:01,207: INFO/MainProcess] celery@rithviz-inspiron7570 ready.
[2021-01-23 22:52:13,972: INFO/MainProcess] Received task: server.tasks.tasks.process_image[61daae8e-e12d-40be-b0e4-156a44122cc0]  
[2021-01-23 22:52:15,644: INFO/ForkPoolWorker-7] server.tasks.tasks.process_image[61daae8e-e12d-40be-b0e4-156a44122cc0]: colortheif done for wp2831915-black-background-png.png
[2021-01-23 22:52:15,696: WARNING/ForkPoolWorker-7] ...............................................................
[2021-01-23 22:52:15,720: INFO/ForkPoolWorker-7] server.tasks.tasks.process_image[61daae8e-e12d-40be-b0e4-156a44122cc0]: vibrant.go done for wp2831915-black-background-png.png
[2021-01-23 22:52:15,720: WARNING/ForkPoolWorker-7] PWD1
[2021-01-23 22:52:15,721: WARNING/ForkPoolWorker-7] /media/rithvij/Storage/Images/pallete/pallete-theme/src
[2021-01-23 22:52:15,721: WARNING/ForkPoolWorker-7] PWD2
[2021-01-23 22:52:15,722: WARNING/ForkPoolWorker-7] /media/rithvij/Storage/Images/pallete/pallete-theme
[2021-01-23 22:52:16,499: WARNING/ForkPoolWorker-7] PWD3
[2021-01-23 22:52:16,500: WARNING/ForkPoolWorker-7] /media/rithvij/Storage/Images/pallete/pallete-theme/src
[2021-01-23 22:52:16,529: INFO/ForkPoolWorker-7] server.tasks.tasks.process_image[61daae8e-e12d-40be-b0e4-156a44122cc0]: node vibrant done for wp2831915-black-background-png.png
[2021-01-23 22:52:16,980: WARNING/ForkPoolWorker-7] ------------------------------
[2021-01-23 22:52:16,981: WARNING/ForkPoolWorker-7] BASTERBASTERBASTERBASTERBASTERBASTERBASTERBASTERBASTERBASTERBASTERBASTERBASTERBASTERBASTERBASTERBASTERBASTERBASTERBASTER
[2021-01-23 22:52:16,982: WARNING/ForkPoolWorker-7] [{'hex': '#000000', 'names': ['Black', 'black', 'Black', 'Midnight Moss', 'Black'], 'similar_colors': ['#000000', '#000000', '#000000', '#041004', '#000000'], 'exact': [True, True, True, False, True], 'count': 186298}, {'hex': '#010000', 'names': ['Black', 'black', 'Black', 'Midnight Moss', 'Black'], 'similar_colors': ['#000000', '#000000', '#000000', '#041004', '#000000'], 'exact': [False, False, False, False, False], 'count': 21}, {'hex': '#020000', 'names': ['Black', 'black', 'Black', 'Midnight Moss', 'Black'], 'similar_colors': ['#000000', '#000000', '#000000', '#041004', '#000000'], 'exact': [False, False, False, False, False], 'count': 10}, {'hex': '#030000', 'names': ['Black', 'black', 'Black', 'Diesel', 'Black'], 'similar_colors': ['#000000', '#000000', '#000000', '#130000', '#000000'], 'exact': [False, False, False, False, False], 'count': 5}, {'hex': '#060100', 'names': ['Black', 'black', 'Rich black (FOGRA39)', 'Diesel', 'Black'], 'similar_colors': ['#000000', '#000000', '#010203', '#130000', '#000000'], 'exact': [False, False, False, False, False], 'count': 4}, {'hex': '#000001', 'names': ['Black', 'black', 'Black', 'Midnight Moss', 'Black'], 'similar_colors': ['#000000', '#000000', '#000000', '#041004', '#000000'], 'exact': [False, False, False, False, False], 'count': 4}, {'hex': '#020101', 'names': ['Black', 'black', 'Black', 'Midnight Moss', 'Black'], 'similar_colors': ['#000000', '#000000', '#000000', '#041004', '#000000'], 'exact': [False, False, False, False, False], 'count': 4}, {'hex': '#010001', 'names': ['Black', 'black', 'Black', 'Midnight Moss', 'Black'], 'similar_colors': ['#000000', '#000000', '#000000', '#041004', '#000000'], 'exact': [False, False, False, False, False], 'count': 4}, {'hex': '#000100', 'names': ['Black', 'black', 'Black', 'Midnight Moss', 'Black'], 'similar_colors': ['#000000', '#000000', '#000000', '#041004', '#000000'], 'exact': [False, False, False, False, False], 'count': 3}, {'hex': '#010100', 'names': ['Black', 'black', 'Black', 'Midnight Moss', 'Black'], 'similar_colors': ['#000000', '#000000', '#000000', '#041004', '#000000'], 'exact': [False, False, False, False, False], 'count': 2}]
[2021-01-23 22:52:16,982: WARNING/ForkPoolWorker-7] ------------------------------
[2021-01-23 22:52:16,990: INFO/ForkPoolWorker-7] server.tasks.tasks.process_image[61daae8e-e12d-40be-b0e4-156a44122cc0]: rgbaster done for wp2831915-black-background-png.png
[2021-01-23 22:52:17,145: INFO/ForkPoolWorker-7] server.tasks.tasks.process_image[61daae8e-e12d-40be-b0e4-156a44122cc0]: colorcube done for wp2831915-black-background-png.png
[2021-01-23 22:52:17,155: WARNING/ForkPoolWorker-7] so long fakhar ***so long fakhar ***so long fakhar ***so long fakhar ***so long fakhar ***so long fakhar ***so long fakhar ***so long fakhar ***so long fakhar ***so long fakhar ***so long fakhar ***so long fakhar ***so long fakhar ***so long fakhar ***so long fakhar ***so long fakhar ***so long fakhar ***so long fakhar ***so long fakhar ***so long fakhar ***
[2021-01-23 22:52:17,155: WARNING/ForkPoolWorker-7] (72, 128)
[2021-01-23 22:52:17,178: ERROR/ForkPoolWorker-7] Task server.tasks.tasks.process_image[61daae8e-e12d-40be-b0e4-156a44122cc0] raised unexpected: IndexError('tuple index out of range')
Traceback (most recent call last):
  File "/media/rithvij/Storage/Images/pallete/pallete-theme/src/venv/lib/python3.9/site-packages/celery/app/trace.py", line 405, in trace_task
    R = retval = fun(*args, **kwargs)
  File "/media/rithvij/Storage/Images/pallete/pallete-theme/src/venv/lib/python3.9/site-packages/celery/app/trace.py", line 697, in __protected_call__
    return self.run(*args, **kwargs)
  File "/media/rithvij/Storage/Images/pallete/pallete-theme/src/venv/lib/python3.9/site-packages/sentry_sdk/integrations/celery.py", line 197, in _inner
    reraise(*exc_info)
  File "/media/rithvij/Storage/Images/pallete/pallete-theme/src/venv/lib/python3.9/site-packages/sentry_sdk/_compat.py", line 54, in reraise
    raise value
  File "/media/rithvij/Storage/Images/pallete/pallete-theme/src/venv/lib/python3.9/site-packages/sentry_sdk/integrations/celery.py", line 192, in _inner
    return f(*args, **kwargs)
  File "/media/rithvij/Storage/Images/pallete/pallete-theme/src/server/tasks/tasks.py", line 112, in process_image
    data["service"] = get_color_service_pallete(file)
  File "/media/rithvij/Storage/Images/pallete/pallete-theme/src/server/utils/colorservice.py", line 31, in get_color_service_pallete
    data = extract_colors_from_file(fp, **kwargs)
  File "/media/rithvij/Storage/Images/pallete/pallete-theme/src/server/utils/colorservice.py", line 66, in extract_colors_from_file
    if img_array.shape[2] > 3:
IndexError: tuple index out of range
[2021-01-24 00:49:31,664: WARNING/MainProcess] consumer: Connection to broker lost. Trying to re-establish the connection...
Traceback (most recent call last):
  File "/media/rithvij/Storage/Images/pallete/pallete-theme/src/venv/lib/python3.9/site-packages/celery/worker/consumer/consumer.py", line 311, in start
    blueprint.start(self)
  File "/media/rithvij/Storage/Images/pallete/pallete-theme/src/venv/lib/python3.9/site-packages/celery/bootsteps.py", line 116, in start
    step.start(parent)
  File "/media/rithvij/Storage/Images/pallete/pallete-theme/src/venv/lib/python3.9/site-packages/celery/worker/consumer/consumer.py", line 592, in start
    c.loop(*c.loop_args())
  File "/media/rithvij/Storage/Images/pallete/pallete-theme/src/venv/lib/python3.9/site-packages/celery/worker/loops.py", line 81, in asynloop
    next(loop)
  File "/media/rithvij/Storage/Images/pallete/pallete-theme/src/venv/lib/python3.9/site-packages/kombu/asynchronous/hub.py", line 305, in create_loop
    events = poll(poll_timeout)
  File "/media/rithvij/Storage/Images/pallete/pallete-theme/src/venv/lib/python3.9/site-packages/kombu/utils/eventio.py", line 82, in poll
    return self._epoll.poll(timeout if timeout is not None else -1)
  File "/media/rithvij/Storage/Images/pallete/pallete-theme/src/venv/lib/python3.9/site-packages/celery/apps/worker.py", line 290, in _handle_request
    safe_say(f'worker: {how} shutdown (MainProcess)')
  File "/media/rithvij/Storage/Images/pallete/pallete-theme/src/venv/lib/python3.9/site-packages/celery/apps/worker.py", line 82, in safe_say
    print(f'\n{msg}', file=sys.__stderr__, flush=True)
OSError: [Errno 5] Input/output error
[2021-01-24 00:49:32,682: ERROR/MainProcess] consumer: Cannot connect to redis://localhost:6379/0: Error 111 connecting to localhost:6379. Connection refused..
Trying again in 2.00 seconds... (1/100)

[2021-01-24 00:49:32,850: WARNING/MainProcess] Retrying (Retry(total=2, connect=None, read=None, redirect=None, status=None)) after connection broken by 'NewConnectionError('<urllib3.connection.HTTPSConnection object at 0x7fb889139df0>: Failed to establish a new connection: [Errno -2] Name or service not known')': /api/5242511/store/
[2021-01-24 00:49:32,853: WARNING/MainProcess] Retrying (Retry(total=1, connect=None, read=None, redirect=None, status=None)) after connection broken by 'NewConnectionError('<urllib3.connection.HTTPSConnection object at 0x7fb889051130>: Failed to establish a new connection: [Errno -2] Name or service not known')': /api/5242511/store/
[2021-01-24 00:49:32,855: WARNING/MainProcess] Retrying (Retry(total=0, connect=None, read=None, redirect=None, status=None)) after connection broken by 'NewConnectionError('<urllib3.connection.HTTPSConnection object at 0x7fb889051280>: Failed to establish a new connection: [Errno -2] Name or service not known')': /api/5242511/store/
[2021-01-24 00:49:34,707: ERROR/MainProcess] consumer: Cannot connect to redis://localhost:6379/0: Error 111 connecting to localhost:6379. Connection refused..
Trying again in 4.00 seconds... (2/100)

[2021-01-24 00:49:34,720: WARNING/MainProcess] Retrying (Retry(total=2, connect=None, read=None, redirect=None, status=None)) after connection broken by 'NewConnectionError('<urllib3.connection.HTTPSConnection object at 0x7fb889180fa0>: Failed to establish a new connection: [Errno -2] Name or service not known')': /api/5242511/store/
[2021-01-24 00:49:34,721: WARNING/MainProcess] Retrying (Retry(total=1, connect=None, read=None, redirect=None, status=None)) after connection broken by 'NewConnectionError('<urllib3.connection.HTTPSConnection object at 0x7fb889051340>: Failed to establish a new connection: [Errno -2] Name or service not known')': /api/5242511/store/
[2021-01-24 00:49:34,722: WARNING/MainProcess] Retrying (Retry(total=0, connect=None, read=None, redirect=None, status=None)) after connection broken by 'NewConnectionError('<urllib3.connection.HTTPSConnection object at 0x7fb8890511c0>: Failed to establish a new connection: [Errno -2] Name or service not known')': /api/5242511/store/
[2021-01-24 00:49:38,725: ERROR/MainProcess] consumer: Cannot connect to redis://localhost:6379/0: Error 111 connecting to localhost:6379. Connection refused..
Trying again in 6.00 seconds... (3/100)

[2021-01-24 00:49:38,740: WARNING/MainProcess] Retrying (Retry(total=2, connect=None, read=None, redirect=None, status=None)) after connection broken by 'NewConnectionError('<urllib3.connection.HTTPSConnection object at 0x7fb8890511c0>: Failed to establish a new connection: [Errno -2] Name or service not known')': /api/5242511/store/
[2021-01-24 00:49:38,740: WARNING/MainProcess] Retrying (Retry(total=1, connect=None, read=None, redirect=None, status=None)) after connection broken by 'NewConnectionError('<urllib3.connection.HTTPSConnection object at 0x7fb889051b80>: Failed to establish a new connection: [Errno -2] Name or service not known')': /api/5242511/store/
[2021-01-24 00:49:38,741: WARNING/MainProcess] Retrying (Retry(total=0, connect=None, read=None, redirect=None, status=None)) after connection broken by 'NewConnectionError('<urllib3.connection.HTTPSConnection object at 0x7fb889051430>: Failed to establish a new connection: [Errno -2] Name or service not known')': /api/5242511/store/
[2021-01-24 00:49:44,747: ERROR/MainProcess] consumer: Cannot connect to redis://localhost:6379/0: Error 111 connecting to localhost:6379. Connection refused..
Trying again in 8.00 seconds... (4/100)

[2021-01-24 00:49:44,761: WARNING/MainProcess] Retrying (Retry(total=2, connect=None, read=None, redirect=None, status=None)) after connection broken by 'NewConnectionError('<urllib3.connection.HTTPSConnection object at 0x7fb889180cd0>: Failed to establish a new connection: [Errno -2] Name or service not known')': /api/5242511/store/
[2021-01-24 00:49:44,762: WARNING/MainProcess] Retrying (Retry(total=1, connect=None, read=None, redirect=None, status=None)) after connection broken by 'NewConnectionError('<urllib3.connection.HTTPSConnection object at 0x7fb8891652b0>: Failed to establish a new connection: [Errno -2] Name or service not known')': /api/5242511/store/
[2021-01-24 00:49:44,762: WARNING/MainProcess] Retrying (Retry(total=0, connect=None, read=None, redirect=None, status=None)) after connection broken by 'NewConnectionError('<urllib3.connection.HTTPSConnection object at 0x7fb8890513a0>: Failed to establish a new connection: [Errno -2] Name or service not known')': /api/5242511/store/
[2021-01-24 00:49:52,771: ERROR/MainProcess] consumer: Cannot connect to redis://localhost:6379/0: Error 111 connecting to localhost:6379. Connection refused..
Trying again in 10.00 seconds... (5/100)

[2021-01-24 00:49:52,784: WARNING/MainProcess] Retrying (Retry(total=2, connect=None, read=None, redirect=None, status=None)) after connection broken by 'NewConnectionError('<urllib3.connection.HTTPSConnection object at 0x7fb889116fa0>: Failed to establish a new connection: [Errno -2] Name or service not known')': /api/5242511/store/
[2021-01-24 00:49:52,785: WARNING/MainProcess] Retrying (Retry(total=1, connect=None, read=None, redirect=None, status=None)) after connection broken by 'NewConnectionError('<urllib3.connection.HTTPSConnection object at 0x7fb889051370>: Failed to establish a new connection: [Errno -2] Name or service not known')': /api/5242511/store/
[2021-01-24 00:49:52,785: WARNING/MainProcess] Retrying (Retry(total=0, connect=None, read=None, redirect=None, status=None)) after connection broken by 'NewConnectionError('<urllib3.connection.HTTPSConnection object at 0x7fb889180940>: Failed to establish a new connection: [Errno -2] Name or service not known')': /api/5242511/store/
[2021-01-24 00:50:02,796: ERROR/MainProcess] consumer: Cannot connect to redis://localhost:6379/0: Error 111 connecting to localhost:6379. Connection refused..
Trying again in 12.00 seconds... (6/100)

[2021-01-24 00:50:02,809: WARNING/MainProcess] Retrying (Retry(total=2, connect=None, read=None, redirect=None, status=None)) after connection broken by 'NewConnectionError('<urllib3.connection.HTTPSConnection object at 0x7fb889180fa0>: Failed to establish a new connection: [Errno -2] Name or service not known')': /api/5242511/store/
[2021-01-24 00:50:02,810: WARNING/MainProcess] Retrying (Retry(total=1, connect=None, read=None, redirect=None, status=None)) after connection broken by 'NewConnectionError('<urllib3.connection.HTTPSConnection object at 0x7fb889180550>: Failed to establish a new connection: [Errno -2] Name or service not known')': /api/5242511/store/
[2021-01-24 00:50:02,810: WARNING/MainProcess] Retrying (Retry(total=0, connect=None, read=None, redirect=None, status=None)) after connection broken by 'NewConnectionError('<urllib3.connection.HTTPSConnection object at 0x7fb889051250>: Failed to establish a new connection: [Errno -2] Name or service not known')': /api/5242511/store/
[2021-01-24 00:50:14,823: ERROR/MainProcess] consumer: Cannot connect to redis://localhost:6379/0: Error 111 connecting to localhost:6379. Connection refused..
Trying again in 14.00 seconds... (7/100)

[2021-01-24 00:50:14,836: WARNING/MainProcess] Retrying (Retry(total=2, connect=None, read=None, redirect=None, status=None)) after connection broken by 'NewConnectionError('<urllib3.connection.HTTPSConnection object at 0x7fb889051400>: Failed to establish a new connection: [Errno -2] Name or service not known')': /api/5242511/store/
[2021-01-24 00:50:14,836: WARNING/MainProcess] Retrying (Retry(total=1, connect=None, read=None, redirect=None, status=None)) after connection broken by 'NewConnectionError('<urllib3.connection.HTTPSConnection object at 0x7fb889180d30>: Failed to establish a new connection: [Errno -2] Name or service not known')': /api/5242511/store/
[2021-01-24 00:50:14,837: WARNING/MainProcess] Retrying (Retry(total=0, connect=None, read=None, redirect=None, status=None)) after connection broken by 'NewConnectionError('<urllib3.connection.HTTPSConnection object at 0x7fb889180af0>: Failed to establish a new connection: [Errno -2] Name or service not known')': /api/5242511/store/
[2021-01-24 00:50:28,853: ERROR/MainProcess] consumer: Cannot connect to redis://localhost:6379/0: Error 111 connecting to localhost:6379. Connection refused..
Trying again in 16.00 seconds... (8/100)

[2021-01-24 00:50:28,867: WARNING/MainProcess] Retrying (Retry(total=2, connect=None, read=None, redirect=None, status=None)) after connection broken by 'NewConnectionError('<urllib3.connection.HTTPSConnection object at 0x7fb8890aed90>: Failed to establish a new connection: [Errno -2] Name or service not known')': /api/5242511/store/
[2021-01-24 00:50:28,867: WARNING/MainProcess] Retrying (Retry(total=1, connect=None, read=None, redirect=None, status=None)) after connection broken by 'NewConnectionError('<urllib3.connection.HTTPSConnection object at 0x7fb889180af0>: Failed to establish a new connection: [Errno -2] Name or service not known')': /api/5242511/store/
[2021-01-24 00:50:28,868: WARNING/MainProcess] Retrying (Retry(total=0, connect=None, read=None, redirect=None, status=None)) after connection broken by 'NewConnectionError('<urllib3.connection.HTTPSConnection object at 0x7fb889116b50>: Failed to establish a new connection: [Errno -2] Name or service not known')': /api/5242511/store/
[2021-01-24 00:50:44,885: ERROR/MainProcess] consumer: Cannot connect to redis://localhost:6379/0: Error 111 connecting to localhost:6379. Connection refused..
Trying again in 18.00 seconds... (9/100)

[2021-01-24 00:50:44,898: WARNING/MainProcess] Retrying (Retry(total=2, connect=None, read=None, redirect=None, status=None)) after connection broken by 'NewConnectionError('<urllib3.connection.HTTPSConnection object at 0x7fb889116b50>: Failed to establish a new connection: [Errno -2] Name or service not known')': /api/5242511/store/
[2021-01-24 00:50:44,899: WARNING/MainProcess] Retrying (Retry(total=1, connect=None, read=None, redirect=None, status=None)) after connection broken by 'NewConnectionError('<urllib3.connection.HTTPSConnection object at 0x7fb889180940>: Failed to establish a new connection: [Errno -2] Name or service not known')': /api/5242511/store/
[2021-01-24 00:50:44,899: WARNING/MainProcess] Retrying (Retry(total=0, connect=None, read=None, redirect=None, status=None)) after connection broken by 'NewConnectionError('<urllib3.connection.HTTPSConnection object at 0x7fb8890ae820>: Failed to establish a new connection: [Errno -2] Name or service not known')': /api/5242511/store/
